<?xml version="1.0"?>
<robot name="my_car">

    <link name="base_link">
        <visual>
            <origin xyz="0.0 0.0 0.1" rpy="0.0 0.0 0.0"/>
            <geometry>
                <box size="0.5 0.4 0.1"/>
            </geometry>
        </visual>
    </link>

    <link name="wheel_1">
        <visual>
            <origin xyz="0.0 0.0 0.0" rpy="1.57 0.0 0.0"/>
            
            <geometry>
                <cylinder radius="0.1" length="0.05"/>
            </geometry>
        </visual>
    </link>

    <joint name="joint_1" type="continuous">
        <parent link="base_link"/>
        <child link="wheel_1"/>
        <axis xyz="0 0 1"/>
        <origin xyz="0.20 0.225 0.1" rpy="0 0 0"/>
    </joint>

</robot>